INFO, 2023-02-23 07:31:22,241, dashboard_function.py - server_BChartDataList - Success
INFO, 2023-02-23 07:31:23,129, dashboard_function.py - service_donutChartData - Success
INFO, 2023-02-23 07:31:24,001, dashboard_function.py - alarmData - Success
INFO, 2023-02-23 07:31:24,464, dashboard_function.py - server_LChartDataList - Success
INFO, 2023-02-23 07:31:24,640, dashboard_function.py - os_donutChartData - Success
INFO, 2023-02-23 07:31:24,875, dashboard_function.py - vendorChartList - Success
INFO, 2023-02-23 07:31:25,042, dashboard_function.py - alarm_donutChartData - Success
INFO, 2023-02-23 07:31:25,435, dashboard_function.py - BNChartDataList - Success
INFO, 2023-02-23 07:31:25,436, dashboard_function.py - WMCDL(World Map Chart Data List) - Success
INFO, 2023-02-23 07:31:25,802, dashboard_function.py - connectIpDataList - Success
INFO, 2023-02-23 07:31:25,984, dashboard_function.py - connectServerDataList - Success
INFO, 2023-02-23 07:31:26,197, dashboard_function.py - memoryMoreDataList - Success
INFO, 2023-02-23 07:41:28,655, dashboard_function.py - server_BChartDataList - Success
INFO, 2023-02-23 07:41:28,737, dashboard_function.py - service_donutChartData - Success
INFO, 2023-02-23 07:41:28,814, dashboard_function.py - alarmData - Success
INFO, 2023-02-23 07:41:28,908, dashboard_function.py - server_LChartDataList - Success
INFO, 2023-02-23 07:41:28,988, dashboard_function.py - os_donutChartData - Success
INFO, 2023-02-23 07:41:29,072, dashboard_function.py - vendorChartList - Success
INFO, 2023-02-23 07:41:29,157, dashboard_function.py - alarm_donutChartData - Success
INFO, 2023-02-23 07:41:29,334, dashboard_function.py - BNChartDataList - Success
INFO, 2023-02-23 07:41:29,334, dashboard_function.py - WMCDL(World Map Chart Data List) - Success
INFO, 2023-02-23 07:41:29,413, dashboard_function.py - GpuServerDataList - Success
INFO, 2023-02-23 07:41:29,489, dashboard_function.py - connectIpDataList - Success
INFO, 2023-02-23 07:41:29,569, dashboard_function.py - connectServerDataList - Success
INFO, 2023-02-23 07:41:29,647, dashboard_function.py - memoryMoreDataList - Success
INFO, 2023-02-23 14:15:14,396, dashboard_function.py - server_BChartDataList - Success
INFO, 2023-02-23 14:15:14,532, dashboard_function.py - service_donutChartData - Success
INFO, 2023-02-23 14:15:14,660, dashboard_function.py - alarmData - Success
INFO, 2023-02-23 14:15:14,804, dashboard_function.py - server_LChartDataList - Success
INFO, 2023-02-23 14:15:14,900, dashboard_function.py - os_donutChartData - Success
INFO, 2023-02-23 14:15:14,996, dashboard_function.py - vendorChartList - Success
INFO, 2023-02-23 14:15:15,092, dashboard_function.py - alarm_donutChartData - Success
INFO, 2023-02-23 14:15:15,260, dashboard_function.py - BNChartDataList - Success
INFO, 2023-02-23 14:15:15,260, dashboard_function.py - WMCDL(World Map Chart Data List) - Success
INFO, 2023-02-23 14:15:15,420, dashboard_function.py - connectIpDataList - Success
INFO, 2023-02-23 14:15:15,516, dashboard_function.py - connectServerDataList - Success
INFO, 2023-02-23 14:15:15,620, dashboard_function.py - memoryMoreDataList - Success
ERROR, 2023-02-23 14:15:15,820, Internal Server Error: /dashboard/
Traceback (most recent call last):
  File "C:\venvs\xion\lib\site-packages\django\contrib\sessions\backends\base.py", line 187, in _get_session
    return self._session_cache
AttributeError: 'SessionStore' object has no attribute '_session_cache'

During handling of the above exception, another exception occurred:

Traceback (most recent call last):
  File "C:\venvs\xion\lib\site-packages\django\db\backends\base\base.py", line 244, in ensure_connection
    self.connect()
  File "C:\venvs\xion\lib\site-packages\django\utils\asyncio.py", line 26, in inner
    return func(*args, **kwargs)
  File "C:\venvs\xion\lib\site-packages\django\db\backends\base\base.py", line 225, in connect
    self.connection = self.get_new_connection(conn_params)
  File "C:\venvs\xion\lib\site-packages\django\utils\asyncio.py", line 26, in inner
    return func(*args, **kwargs)
  File "C:\venvs\xion\lib\site-packages\django\db\backends\postgresql\base.py", line 203, in get_new_connection
    connection = Database.connect(**conn_params)
  File "C:\venvs\xion\lib\site-packages\psycopg2\__init__.py", line 122, in connect
    conn = _connect(dsn, connection_factory=connection_factory, **kwasync)
psycopg2.OperationalError: connection to server at "1.223.168.93", port 40011 failed: No route to host (0x00002751/10065)
	Is the server running on that host and accepting TCP/IP connections?


The above exception was the direct cause of the following exception:

Traceback (most recent call last):
  File "C:\venvs\xion\lib\site-packages\django\core\handlers\exception.py", line 55, in inner
    response = get_response(request)
  File "C:\venvs\xion\lib\site-packages\django\core\handlers\base.py", line 197, in _get_response
    response = wrapped_callback(request, *callback_args, **callback_kwargs)
  File "C:\Users\isaac\PycharmProjects\X-Factor\web\views\base_views.py", line 34, in dashboard
    if not 'sessionid' in request.session:
  File "C:\venvs\xion\lib\site-packages\django\contrib\sessions\backends\base.py", line 50, in __contains__
    return key in self._session
  File "C:\venvs\xion\lib\site-packages\django\contrib\sessions\backends\base.py", line 192, in _get_session
    self._session_cache = self.load()
  File "C:\venvs\xion\lib\site-packages\django\contrib\sessions\backends\db.py", line 42, in load
    s = self._get_session_from_db()
  File "C:\venvs\xion\lib\site-packages\django\contrib\sessions\backends\db.py", line 32, in _get_session_from_db
    return self.model.objects.get(
  File "C:\venvs\xion\lib\site-packages\django\db\models\manager.py", line 85, in manager_method
    return getattr(self.get_queryset(), name)(*args, **kwargs)
  File "C:\venvs\xion\lib\site-packages\django\db\models\query.py", line 492, in get
    num = len(clone)
  File "C:\venvs\xion\lib\site-packages\django\db\models\query.py", line 302, in __len__
    self._fetch_all()
  File "C:\venvs\xion\lib\site-packages\django\db\models\query.py", line 1507, in _fetch_all
    self._result_cache = list(self._iterable_class(self))
  File "C:\venvs\xion\lib\site-packages\django\db\models\query.py", line 57, in __iter__
    results = compiler.execute_sql(
  File "C:\venvs\xion\lib\site-packages\django\db\models\sql\compiler.py", line 1359, in execute_sql
    cursor = self.connection.cursor()
  File "C:\venvs\xion\lib\site-packages\django\utils\asyncio.py", line 26, in inner
    return func(*args, **kwargs)
  File "C:\venvs\xion\lib\site-packages\django\db\backends\base\base.py", line 284, in cursor
    return self._cursor()
  File "C:\venvs\xion\lib\site-packages\django\db\backends\base\base.py", line 260, in _cursor
    self.ensure_connection()
  File "C:\venvs\xion\lib\site-packages\django\utils\asyncio.py", line 26, in inner
    return func(*args, **kwargs)
  File "C:\venvs\xion\lib\site-packages\django\db\backends\base\base.py", line 243, in ensure_connection
    with self.wrap_database_errors:
  File "C:\venvs\xion\lib\site-packages\django\db\utils.py", line 91, in __exit__
    raise dj_exc_value.with_traceback(traceback) from exc_value
  File "C:\venvs\xion\lib\site-packages\django\db\backends\base\base.py", line 244, in ensure_connection
    self.connect()
  File "C:\venvs\xion\lib\site-packages\django\utils\asyncio.py", line 26, in inner
    return func(*args, **kwargs)
  File "C:\venvs\xion\lib\site-packages\django\db\backends\base\base.py", line 225, in connect
    self.connection = self.get_new_connection(conn_params)
  File "C:\venvs\xion\lib\site-packages\django\utils\asyncio.py", line 26, in inner
    return func(*args, **kwargs)
  File "C:\venvs\xion\lib\site-packages\django\db\backends\postgresql\base.py", line 203, in get_new_connection
    connection = Database.connect(**conn_params)
  File "C:\venvs\xion\lib\site-packages\psycopg2\__init__.py", line 122, in connect
    conn = _connect(dsn, connection_factory=connection_factory, **kwasync)
django.db.utils.OperationalError: connection to server at "1.223.168.93", port 40011 failed: No route to host (0x00002751/10065)
	Is the server running on that host and accepting TCP/IP connections?

WARNING, 2023-02-23 14:15:15,964, Not Found: /favicon.ico
